<?xml version="1.0"?>
<!--
  Self-contained 6-DOF "skeleton" arm for in-app visualization/verification of
  grasp-search results (see CLAUDE.md AI 向けガード: this app never solves IK —
  it only displays poses/joint angles it receives). All links use primitive
  <geometry> (box/cylinder) so no external mesh assets are required; URDFLoader
  builds THREE.BoxGeometry/CylinderGeometry directly from this file. World
  frame follows ROS REP-103 (+X forward, +Y left, +Z up).
-->
<robot name="skeleton_arm">

  <material name="base_gray">
    <color rgba="0.25 0.27 0.30 1"/>
  </material>
  <material name="link_blue">
    <color rgba="0.35 0.55 0.85 1"/>
  </material>
  <material name="flange_orange">
    <color rgba="0.95 0.55 0.15 1"/>
  </material>

  <link name="base_link">
    <visual>
      <origin xyz="0 0 0.04" rpy="0 0 0"/>
      <geometry><box size="0.16 0.16 0.08"/></geometry>
      <material name="base_gray"/>
    </visual>
  </link>

  <joint name="shoulder_pan_joint" type="revolute">
    <parent link="base_link"/>
    <child link="shoulder_link"/>
    <origin xyz="0 0 0.08" rpy="0 0 0"/>
    <axis xyz="0 0 1"/>
    <limit lower="-2.967" upper="2.967" effort="150" velocity="3.14"/>
  </joint>

  <link name="shoulder_link">
    <visual>
      <origin xyz="0 0 0.06" rpy="0 0 0"/>
      <geometry><cylinder radius="0.055" length="0.12"/></geometry>
      <material name="link_blue"/>
    </visual>
  </link>

  <joint name="shoulder_lift_joint" type="revolute">
    <parent link="shoulder_link"/>
    <child link="upper_arm_link"/>
    <origin xyz="0 0 0.12" rpy="0 0 0"/>
    <axis xyz="0 1 0"/>
    <limit lower="-2.0944" upper="2.0944" effort="150" velocity="3.14"/>
  </joint>

  <link name="upper_arm_link">
    <visual>
      <origin xyz="0 0 0.15" rpy="0 0 0"/>
      <geometry><cylinder radius="0.045" length="0.30"/></geometry>
      <material name="link_blue"/>
    </visual>
  </link>

  <joint name="elbow_joint" type="revolute">
    <parent link="upper_arm_link"/>
    <child link="forearm_link"/>
    <origin xyz="0 0 0.30" rpy="0 0 0"/>
    <axis xyz="0 1 0"/>
    <limit lower="-2.618" upper="2.618" effort="100" velocity="3.14"/>
  </joint>

  <link name="forearm_link">
    <visual>
      <origin xyz="0 0 0.125" rpy="0 0 0"/>
      <geometry><cylinder radius="0.035" length="0.25"/></geometry>
      <material name="link_blue"/>
    </visual>
  </link>

  <joint name="wrist_1_joint" type="revolute">
    <parent link="forearm_link"/>
    <child link="wrist_1_link"/>
    <origin xyz="0 0 0.25" rpy="0 0 0"/>
    <axis xyz="0 1 0"/>
    <limit lower="-3.14159" upper="3.14159" effort="30" velocity="6.28"/>
  </joint>

  <link name="wrist_1_link">
    <visual>
      <origin xyz="0 0 0.04" rpy="0 0 0"/>
      <geometry><cylinder radius="0.03" length="0.08"/></geometry>
      <material name="base_gray"/>
    </visual>
  </link>

  <joint name="wrist_2_joint" type="revolute">
    <parent link="wrist_1_link"/>
    <child link="wrist_2_link"/>
    <origin xyz="0 0 0.08" rpy="0 0 0"/>
    <axis xyz="1 0 0"/>
    <limit lower="-3.14159" upper="3.14159" effort="30" velocity="6.28"/>
  </joint>

  <link name="wrist_2_link">
    <visual>
      <origin xyz="0 0 0.03" rpy="0 0 0"/>
      <geometry><cylinder radius="0.025" length="0.06"/></geometry>
      <material name="base_gray"/>
    </visual>
  </link>

  <joint name="wrist_3_joint" type="revolute">
    <parent link="wrist_2_link"/>
    <child link="flange"/>
    <origin xyz="0 0 0.06" rpy="0 0 0"/>
    <axis xyz="0 0 1"/>
    <limit lower="-3.14159" upper="3.14159" effort="30" velocity="6.28"/>
  </joint>

  <link name="flange">
    <visual>
      <origin xyz="0 0 0.01" rpy="0 0 0"/>
      <geometry><box size="0.05 0.05 0.02"/></geometry>
      <material name="flange_orange"/>
    </visual>
  </link>

</robot>
